
[2021-04-09 14:04:06] Traceback (most recent call last):
  File "v8function_handler.pyx", line 48, in cefpython_py37.V8FunctionHandler_Execute
  File "/media/feodoritiy/HDD/CODE/VS_C+/fti/Cursach/client/logic/register.py", line 16, in register
    res = json.loads(res.text)
  File "/usr/lib/python3.7/json/__init__.py", line 348, in loads
    return _default_decoder.decode(s)
  File "/usr/lib/python3.7/json/decoder.py", line 337, in decode
    obj, end = self.raw_decode(s, idx=_w(s, 0).end())
  File "/usr/lib/python3.7/json/decoder.py", line 355, in raw_decode
    raise JSONDecodeError("Expecting value", s, err.value) from None
json.decoder.JSONDecodeError: Expecting value: line 1 column 1 (char 0)


[2021-04-09 23:53:30] Traceback (most recent call last):
  File "v8function_handler.pyx", line 48, in cefpython_py37.V8FunctionHandler_Execute
  File "/media/feodoritiy/HDD/CODE/VS_C+/fti/Cursach/client/logic/register.py", line 19, in register
    return res.status
AttributeError: 'dict' object has no attribute 'status'


[2021-04-10 00:50:28] Traceback (most recent call last):
  File "v8function_handler.pyx", line 48, in cefpython_py37.V8FunctionHandler_Execute
  File "/media/feodoritiy/HDD/CODE/VS_C+/fti/Cursach/client/logic/register.py", line 21, in register
    storage.id = res['id']
NameError: name 'storage' is not defined


[2021-04-10 01:29:01] Traceback (most recent call last):
  File "v8function_handler.pyx", line 48, in cefpython_py37.V8FunctionHandler_Execute
  File "/media/feodoritiy/HDD/CODE/VS_C+/fti/Cursach/client/logic/login.py", line 17, in login
    res = json.loads(res.text)
  File "/usr/lib/python3.7/json/__init__.py", line 348, in loads
    return _default_decoder.decode(s)
  File "/usr/lib/python3.7/json/decoder.py", line 337, in decode
    obj, end = self.raw_decode(s, idx=_w(s, 0).end())
  File "/usr/lib/python3.7/json/decoder.py", line 355, in raw_decode
    raise JSONDecodeError("Expecting value", s, err.value) from None
json.decoder.JSONDecodeError: Expecting value: line 1 column 1 (char 0)


[2021-04-10 01:30:08] Traceback (most recent call last):
  File "v8function_handler.pyx", line 48, in cefpython_py37.V8FunctionHandler_Execute
  File "/media/feodoritiy/HDD/CODE/VS_C+/fti/Cursach/client/logic/login.py", line 17, in login
    res = json.loads(res.text)
  File "/usr/lib/python3.7/json/__init__.py", line 348, in loads
    return _default_decoder.decode(s)
  File "/usr/lib/python3.7/json/decoder.py", line 337, in decode
    obj, end = self.raw_decode(s, idx=_w(s, 0).end())
  File "/usr/lib/python3.7/json/decoder.py", line 355, in raw_decode
    raise JSONDecodeError("Expecting value", s, err.value) from None
json.decoder.JSONDecodeError: Expecting value: line 1 column 1 (char 0)


[2021-04-10 01:32:01] Traceback (most recent call last):
  File "v8function_handler.pyx", line 48, in cefpython_py37.V8FunctionHandler_Execute
  File "/media/feodoritiy/HDD/CODE/VS_C+/fti/Cursach/client/logic/login.py", line 17, in login
    res = json.loads(res.text)
  File "/usr/lib/python3.7/json/__init__.py", line 348, in loads
    return _default_decoder.decode(s)
  File "/usr/lib/python3.7/json/decoder.py", line 337, in decode
    obj, end = self.raw_decode(s, idx=_w(s, 0).end())
  File "/usr/lib/python3.7/json/decoder.py", line 355, in raw_decode
    raise JSONDecodeError("Expecting value", s, err.value) from None
json.decoder.JSONDecodeError: Expecting value: line 1 column 1 (char 0)


[2021-04-10 01:33:08] Traceback (most recent call last):
  File "v8function_handler.pyx", line 48, in cefpython_py37.V8FunctionHandler_Execute
  File "/media/feodoritiy/HDD/CODE/VS_C+/fti/Cursach/client/logic/login.py", line 17, in login
    res = json.loads(res.text)
  File "/usr/lib/python3.7/json/__init__.py", line 348, in loads
    return _default_decoder.decode(s)
  File "/usr/lib/python3.7/json/decoder.py", line 337, in decode
    obj, end = self.raw_decode(s, idx=_w(s, 0).end())
  File "/usr/lib/python3.7/json/decoder.py", line 355, in raw_decode
    raise JSONDecodeError("Expecting value", s, err.value) from None
json.decoder.JSONDecodeError: Expecting value: line 1 column 1 (char 0)


[2021-04-10 01:34:28] Traceback (most recent call last):
  File "v8function_handler.pyx", line 48, in cefpython_py37.V8FunctionHandler_Execute
  File "/media/feodoritiy/HDD/CODE/VS_C+/fti/Cursach/client/logic/login.py", line 17, in login
    res = json.loads(res.text)
  File "/usr/lib/python3.7/json/__init__.py", line 348, in loads
    return _default_decoder.decode(s)
  File "/usr/lib/python3.7/json/decoder.py", line 337, in decode
    obj, end = self.raw_decode(s, idx=_w(s, 0).end())
  File "/usr/lib/python3.7/json/decoder.py", line 355, in raw_decode
    raise JSONDecodeError("Expecting value", s, err.value) from None
json.decoder.JSONDecodeError: Expecting value: line 1 column 1 (char 0)


[2021-04-11 23:10:19] Traceback (most recent call last):
  File "v8function_handler.pyx", line 48, in cefpython_py37.V8FunctionHandler_Execute
  File "/media/feodoritiy/HDD/CODE/VS_C+/fti/Cursach/client/logic/shop.py", line 20, in get_shop
    'id': storage.id,
TypeError: 'cefpython_py37.JavascriptCallback' object is not callable


[2021-04-12 00:29:32] Traceback (most recent call last):
  File "v8function_handler.pyx", line 48, in cefpython_py37.V8FunctionHandler_Execute
  File "/media/feodoritiy/HDD/CODE/VS_C+/fti/Cursach/client/logic/shop.py", line 22, in get_shop
    'shop': res.shop,
AttributeError: 'dict' object has no attribute 'shop'


[2021-04-12 21:55:41] Traceback (most recent call last):
  File "v8function_handler.pyx", line 48, in cefpython_py37.V8FunctionHandler_Execute
  File "/media/feodoritiy/HDD/CODE/VS_C+/fti/Cursach/client/logic/shop.py", line 19, in get_shop
    if (res['status'] == 'OK'):
TypeError: 'Response' object is not subscriptable


[2021-04-12 21:57:44] Traceback (most recent call last):
  File "v8function_handler.pyx", line 48, in cefpython_py37.V8FunctionHandler_Execute
  File "/media/feodoritiy/HDD/CODE/VS_C+/fti/Cursach/client/logic/shop.py", line 19, in get_shop
    if (res['status'] == 'OK'):
TypeError: 'Response' object is not subscriptable


[2021-04-12 22:02:02] Traceback (most recent call last):
  File "v8function_handler.pyx", line 48, in cefpython_py37.V8FunctionHandler_Execute
  File "/media/feodoritiy/HDD/CODE/VS_C+/fti/Cursach/client/logic/shop.py", line 19, in get_shop
    if (res['status'] == 'OK'):
TypeError: 'Response' object is not subscriptable


[2021-04-12 22:04:24] Traceback (most recent call last):
  File "v8function_handler.pyx", line 48, in cefpython_py37.V8FunctionHandler_Execute
  File "/media/feodoritiy/HDD/CODE/VS_C+/fti/Cursach/client/logic/shop.py", line 19, in get_shop
    if (res['status'] == 'OK'):
TypeError: 'Response' object is not subscriptable


[2021-04-12 22:45:10] Traceback (most recent call last):
  File "v8function_handler.pyx", line 48, in cefpython_py37.V8FunctionHandler_Execute
  File "/media/feodoritiy/HDD/CODE/VS_C+/fti/Cursach/client/logic/shop.py", line 41, in shop_select
    if res['status'] == 'OK':
TypeError: 'Response' object is not subscriptable


[2021-04-12 23:05:17] Traceback (most recent call last):
  File "v8function_handler.pyx", line 48, in cefpython_py37.V8FunctionHandler_Execute
  File "/media/feodoritiy/HDD/CODE/VS_C+/fti/Cursach/client/logic/shop.py", line 41, in shop_select
    if res['status'] == 'OK':
TypeError: 'Response' object is not subscriptable


[2021-04-12 23:06:47] Traceback (most recent call last):
  File "v8function_handler.pyx", line 48, in cefpython_py37.V8FunctionHandler_Execute
  File "/media/feodoritiy/HDD/CODE/VS_C+/fti/Cursach/client/logic/shop.py", line 41, in shop_select
    if res['status'] == 'OK':
TypeError: 'Response' object is not subscriptable


[2021-04-14 00:20:35] Traceback (most recent call last):
  File "/usr/lib/python3/dist-packages/urllib3/connection.py", line 160, in _new_conn
    (self._dns_host, self.port), self.timeout, **extra_kw
  File "/usr/lib/python3/dist-packages/urllib3/util/connection.py", line 84, in create_connection
    raise err
  File "/usr/lib/python3/dist-packages/urllib3/util/connection.py", line 74, in create_connection
    sock.connect(sa)
ConnectionRefusedError: [Errno 111] Connection refused

During handling of the above exception, another exception occurred:

Traceback (most recent call last):
  File "/usr/lib/python3/dist-packages/urllib3/connectionpool.py", line 672, in urlopen
    chunked=chunked,
  File "/usr/lib/python3/dist-packages/urllib3/connectionpool.py", line 387, in _make_request
    conn.request(method, url, **httplib_request_kw)
  File "/usr/lib/python3.7/http/client.py", line 1277, in request
    self._send_request(method, url, body, headers, encode_chunked)
  File "/usr/lib/python3.7/http/client.py", line 1323, in _send_request
    self.endheaders(body, encode_chunked=encode_chunked)
  File "/usr/lib/python3.7/http/client.py", line 1272, in endheaders
    self._send_output(message_body, encode_chunked=encode_chunked)
  File "/usr/lib/python3.7/http/client.py", line 1032, in _send_output
    self.send(msg)
  File "/usr/lib/python3.7/http/client.py", line 972, in send
    self.connect()
  File "/usr/lib/python3/dist-packages/urllib3/connection.py", line 187, in connect
    conn = self._new_conn()
  File "/usr/lib/python3/dist-packages/urllib3/connection.py", line 172, in _new_conn
    self, "Failed to establish a new connection: %s" % e
urllib3.exceptions.NewConnectionError: <urllib3.connection.HTTPConnection object at 0x7f3b48e4d5d0>: Failed to establish a new connection: [Errno 111] Connection refused

During handling of the above exception, another exception occurred:

Traceback (most recent call last):
  File "/usr/lib/python3/dist-packages/requests/adapters.py", line 449, in send
    timeout=timeout
  File "/usr/lib/python3/dist-packages/urllib3/connectionpool.py", line 720, in urlopen
    method, url, error=e, _pool=self, _stacktrace=sys.exc_info()[2]
  File "/usr/lib/python3/dist-packages/urllib3/util/retry.py", line 436, in increment
    raise MaxRetryError(_pool, url, error or ResponseError(cause))
urllib3.exceptions.MaxRetryError: HTTPConnectionPool(host='127.0.0.1', port=1234): Max retries exceeded with url: /login (Caused by NewConnectionError('<urllib3.connection.HTTPConnection object at 0x7f3b48e4d5d0>: Failed to establish a new connection: [Errno 111] Connection refused'))

During handling of the above exception, another exception occurred:

Traceback (most recent call last):
  File "v8function_handler.pyx", line 48, in cefpython_py37.V8FunctionHandler_Execute
  File "/media/feodoritiy/HDD/CODE/VS_C+/fti/Cursach/client/logic/login.py", line 10, in login
    'password': password,
  File "/media/feodoritiy/HDD/CODE/VS_C+/fti/Cursach/client/storage.py", line 19, in load
    res = requests.post(f'{SERVER}{path}', data)
  File "/usr/lib/python3/dist-packages/requests/api.py", line 116, in post
    return request('post', url, data=data, json=json, **kwargs)
  File "/usr/lib/python3/dist-packages/requests/api.py", line 60, in request
    return session.request(method=method, url=url, **kwargs)
  File "/usr/lib/python3/dist-packages/requests/sessions.py", line 533, in request
    resp = self.send(prep, **send_kwargs)
  File "/usr/lib/python3/dist-packages/requests/sessions.py", line 646, in send
    r = adapter.send(request, **kwargs)
  File "/usr/lib/python3/dist-packages/requests/adapters.py", line 516, in send
    raise ConnectionError(e, request=request)
requests.exceptions.ConnectionError: HTTPConnectionPool(host='127.0.0.1', port=1234): Max retries exceeded with url: /login (Caused by NewConnectionError('<urllib3.connection.HTTPConnection object at 0x7f3b48e4d5d0>: Failed to establish a new connection: [Errno 111] Connection refused'))

